# try:
#     print(x)
# except:
#     print("An exception ocurred")


x = 25
try:
    print(x)
except:
    print("An exception ocurred")
